Workbook

Sheet DATASET 25%
B1: Santa Claus | C1: Gandalf the Grey | D1: Frodo Baggins | E1: Anna | F1: Olaf | G1: Wall-E | H1: Jack Sparrow | I1: Voldemort | J1: Harry Potter | K1: Hagrid | L1: Hermione Granger | M1: Batman | N1: Superman | O1: Minion | P1: Wednesday Adams | Q1: Woody | R1: Captain Kirk | S1: Wolverine | T1: Forrest Gump | U1: Darth Vader | V1: James Bond | W1: Indiana Jones | X1: Barbie | Y1: Cinderella | Z1: Rapunzel | AA1: Pocahontas | AB1: Kermit the Frog | AC1: Miss Piggy | AD1: The Joker | AE1: Katniss Everdeen | AF1: Hannibal Lector | AG1: Chandler Bing | AH1: Rachel Green | AI1: Ross Geller | AJ1: Phoebe Buffay | AK1: Joey Tribiani | AL1: Monica Geller | AM1: Winnie the Pooh | AN1: Dorothy | AO1: Jason Bourne | AP1: Kevin McCallister | AQ1: Regina George | AR1: Shrek | AS1: Professor Snape | AT1: Mr. Bean | AU1: Willy Wonka | AV1: Truman Burbank | AW1: Rudolf the Red-Nosed Reindeer | AX1: Dracula | AY1: Sherlock Holmes
A2: Lord of the Rings: Return of the King | B2: 3 | C2: 4 | D2: 5 | F2: 3 | H2: 5 | I2: 3 | J2: 5 | L2: 2 | M2: 2 | N2: 4 | O2: 2 | Q2: 4 | R2: 5 | S2: 4 | U2: 3 | V2: 4 | W2: 5 | X2: 2 | Z2: 3 | AA2: 4 | AC2: 5 | AD2: 2 | AE2: 5 | AG2: 2 | AH2: 2 | AI2: 4 | AK2: 4 | AL2: 4 | AM2: 2 | AN2: 3 | AP2: 5 | AQ2: 2 | AR2: 4 | AT2: 2 | AU2: 2 | AV2: 3 | AW2: 2 | AY2: 4
A3: Star Wars: The Last Jedi | B3: 2 | C3: 1 | E3: 1 | F3: 3 | G3: 5 | H3: 1 | I3: 4 | L3: 2 | M3: 4 | N3: 4 | Q3: 2 | R3: 5 | T3: 2 | U3: 4 | W3: 4 | X3: 1 | Y3: 2 | Z3: 1 | AB3: 4 | AC3: 5 | AE3: 4 | AF3: 3 | AH3: 4 | AI3: 5 | AJ3: 5 | AK3: 5 | AM3: 2 | AN3: 5 | AO3: 4 | AP3: 5 | AQ3: 1 | AS3: 5 | AT3: 1 | AV3: 4 | AX3: 4 | AY3: 2
A4: The Shawshank Redemption | C4: 5 | D4: 2 | E4: 1 | G4: 2 | H4: 5 | I4: 3 | J4: 4 | K4: 4 | L4: 4 | N4: 2 | O4: 2 | Q4: 3 | S4: 3 | T4: 2 | U4: 2 | V4: 4 | W4: 5 | Z4: 2 | AA4: 3 | AB4: 2 | AC4: 5 | AD4: 5 | AE4: 3 | AF4: 5 | AG4: 2 | AI4: 4 | AJ4: 1 | AK4: 1 | AM4: 2 | AN4: 2 | AO4: 2 | AQ4: 2 | AR4: 1 | AS4: 3 | AT4: 2 | AU4: 2 | AW4: 3 | AX4: 2
A5: Titanic | B5: 4 | D5: 2 | F5: 4 | G5: 4 | H5: 2 | I5: 2 | J5: 3 | K5: 5 | M5: 2 | O5: 5 | P5: 1 | Q5: 4 | R5: 3 | T5: 4 | U5: 1 | V5: 3 | W5: 4 | X5: 5 | Z5: 4 | AA5: 4 | AB5: 5 | AC5: 5 | AD5: 1 | AE5: 2 | AG5: 4 | AH5: 5 | AI5: 4 | AK5: 3 | AL5: 2 | AM5: 3 | AN5: 3 | AP5: 1 | AQ5: 3 | AR5: 2 | AT5: 4 | AU5: 2 | AV5: 2 | AW5: 4 | AY5: 2
A6: The Holiday | C6: 5 | E6: 4 | G6: 4 | K6: 4 | L6: 3 | M6: 1 | N6: 3 | O6: 4 | P6: 1 | R6: 2 | S6: 1 | T6: 4 | U6: 1 | V6: 2 | X6: 5 | Y6: 5 | AA6: 3 | AB6: 5 | AD6: 1 | AE6: 2 | AF6: 2 | AG6: 5 | AK6: 2 | AL6: 1 | AN6: 4 | AO6: 3 | AP6: 3 | AR6: 1 | AS6: 1 | AU6: 3 | AV6: 3 | AW6: 5 | AY6: 2
A7: How the Grinch Stole Christmas | B7: 5 | C7: 5 | E7: 5 | F7: 5 | G7: 2 | H7: 2 | J7: 4 | K7: 5 | L7: 2 | M7: 1 | N7: 2 | O7: 5 | P7: 1 | Q7: 1 | S7: 1 | T7: 5 | U7: 4 | X7: 5 | Y7: 4 | Z7: 4 | AB7: 5 | AC7: 3 | AD7: 5 | AE7: 1 | AF7: 4 | AH7: 3 | AI7: 2 | AJ7: 5 | AL7: 3 | AM7: 3 | AN7: 3 | AO7: 4 | AP7: 4 | AQ7: 1 | AS7: 1 | AT7: 5 | AU7: 3 | AW7: 5 | AX7: 3 | AY7: 4
A8: The Lion King | B8: 5 | C8: 5 | D8: 4 | E8: 5 | F8: 3 | H8: 4 | I8: 3 | J8: 4 | L8: 3 | M8: 2 | N8: 4 | Q8: 4 | R8: 3 | S8: 3 | T8: 5 | V8: 4 | W8: 3 | X8: 5 | Y8: 4 | Z8: 4 | AA8: 5 | AD8: 4 | AE8: 1 | AF8: 4 | AG8: 5 | AH8: 2 | AI8: 3 | AK8: 5 | AL8: 3 | AM8: 4 | AN8: 2 | AP8: 4 | AQ8: 2 | AR8: 4 | AT8: 5 | AU8: 2 | AV8: 5 | AW8: 5 | AX8: 2
A9: Frozen | B9: 5 | D9: 1 | E9: 5 | F9: 5 | G9: 4 | I9: 2 | J9: 2 | K9: 4 | L9: 2 | N9: 2 | O9: 5 | P9: 1 | R9: 2 | S9: 1 | T9: 5 | V9: 3 | W9: 2 | Y9: 5 | Z9: 3 | AA9: 3 | AB9: 5 | AC9: 4 | AD9: 2 | AF9: 2 | AG9: 3 | AH9: 5 | AJ9: 5 | AK9: 5 | AM9: 3 | AO9: 2 | AP9: 2 | AR9: 4 | AS9: 1 | AU9: 4 | AV9: 2 | AX9: 3 | AY9: 1
A10: It | C10: 2 | D10: 1 | E10: 1 | G10: 1 | H10: 3 | I10: 4 | J10: 2 | K10: 1 | L10: 2 | M10: 4 | N10: 3 | O10: 1 | P10: 4 | Q10: 2 | R10: 3 | S10: 4 | U10: 5 | W10: 2 | X10: 2 | Y10: 1 | Z10: 2 | AC10: 4 | AD10: 5 | AF10: 4 | AG10: 2 | AI10: 2 | AJ10: 2 | AK10: 1 | AL10: 3 | AN10: 2 | AO10: 3 | AP10: 4 | AQ10: 3 | AR10: 3 | AT10: 3 | AV10: 1 | AW10: 2 | AX10: 4
A11: The Hills Have Eyes | B11: 1 | D11: 2 | F11: 1 | G11: 1 | H11: 3 | I11: 5 | M11: 3 | N11: 4 | O11: 2 | P11: 5 | R11: 3 | T11: 1 | U11: 3 | V11: 3 | W11: 4 | X11: 2 | Y11: 1 | Z11: 2 | AA11: 3 | AB11: 2 | AC11: 3 | AD11: 4 | AE11: 3 | AF11: 5 | AH11: 1 | AJ11: 3 | AK11: 1 | AM11: 2 | AN11: 2 | AO11: 4 | AP11: 5 | AQ11: 3 | AS11: 3 | AT11: 2 | AU11: 1 | AV11: 2 | AW11: 2 | AX11: 5 | AY11: 3
A12: Grease | C12: 2 | E12: 4 | F12: 5 | G12: 3 | H12: 2 | I12: 2 | J12: 2 | K12: 4 | L12: 3 | M12: 2 | O12: 4 | P12: 1 | R12: 2 | S12: 1 | T12: 5 | U12: 2 | V12: 2 | W12: 3 | X12: 4 | Y12: 5 | AA12: 4 | AC12: 5 | AD12: 1 | AG12: 4 | AH12: 5 | AI12: 4 | AJ12: 2 | AL12: 2 | AM12: 3 | AN12: 3 | AP12: 2 | AR12: 2 | AS12: 1 | AT12: 2 | AU12: 2 | AV12: 3 | AW12: 3 | AX12: 2 | AY12: 1
A13: Mamma Mia! | B13: 5 | E13: 5 | F13: 5 | G13: 4 | I13: 1 | J13: 2 | K13: 3 | L13: 2 | O13: 5 | P13: 1 | Q13: 2 | S13: 1 | U13: 3 | V13: 2 | X13: 5 | Z13: 5 | AB13: 5 | AE13: 2 | AF13: 2 | AG13: 4 | AI13: 4 | AK13: 1 | AL13: 3 | AM13: 2 | AN13: 3 | AP13: 1 | AQ13: 3 | AR13: 1 | AT13: 3 | AU13: 3 | AW13: 3 | AY13: 2
A14: The Princess Diaries | B14: 4 | D14: 2 | E14: 5 | F14: 4 | G14: 2 | J14: 1 | L14: 1 | M14: 1 | N14: 2 | P14: 1 | Q14: 4 | R14: 2 | S14: 1 | T14: 5 | U14: 2 | V14: 3 | W14: 2 | Y14: 5 | Z14: 3 | AA14: 2 | AB14: 5 | AC14: 5 | AD14: 1 | AE14: 1 | AF14: 3 | AG14: 5 | AI14: 2 | AJ14: 5 | AK14: 2 | AL14: 3 | AN14: 4 | AO14: 1 | AP14: 1 | AR14: 4 | AS14: 1 | AT14: 4 | AV14: 2 | AW14: 4 | AX14: 1 | AY14: 1
A15: Twilight | B15: 2 | D15: 3 | E15: 5 | F15: 2 | H15: 2 | I15: 3 | J15: 3 | K15: 4 | M15: 1 | N15: 4 | Q15: 3 | R15: 3 | S15: 3 | T15: 4 | U15: 4 | W15: 2 | X15: 4 | Y15: 3 | Z15: 2 | AA15: 4 | AB15: 3 | AC15: 5 | AE15: 4 | AF15: 5 | AG15: 4 | AH15: 4 | AJ15: 1 | AK15: 1 | AL15: 2 | AM15: 2 | AN15: 2 | AO15: 1 | AQ15: 5 | AR15: 3 | AS15: 2 | AU15: 4 | AV15: 2 | AX15: 5 | AY15: 2
A16: The Breakfast Club | B16: 3 | C16: 4 | D16: 4 | E16: 4 | F16: 2 | G16: 2 | H16: 4 | I16: 2 | J16: 1 | L16: 4 | M16: 2 | N16: 4 | O16: 1 | P16: 1 | R16: 3 | T16: 3 | V16: 4 | W16: 3 | X16: 2 | Y16: 2 | AA16: 4 | AC16: 3 | AD16: 1 | AF16: 2 | AG16: 2 | AI16: 2 | AJ16: 1 | AL16: 4 | AM16: 4 | AN16: 4 | AP16: 1 | AR16: 2 | AS16: 1 | AT16: 3 | AU16: 4 | AV16: 4 | AW16: 3 | AX16: 2 | AY16: 3
A17: E.T. | C17: 5 | D17: 4 | E17: 3 | F17: 5 | G17: 5 | H17: 3 | I17: 4 | K17: 4 | L17: 3 | M17: 3 | O17: 4 | P17: 2 | Q17: 4 | R17: 5 | S17: 4 | T17: 5 | U17: 3 | Y17: 2 | Z17: 2 | AA17: 4 | AB17: 5 | AD17: 5 | AE17: 4 | AF17: 3 | AG17: 5 | AH17: 5 | AI17: 1 | AJ17: 5 | AK17: 5 | AM17: 3 | AN17: 4 | AO17: 3 | AP17: 5 | AQ17: 2 | AT17: 4 | AU17: 4 | AW17: 4 | AX17: 5
A18: Into the Wild | B18: 2 | C18: 4 | D18: 5 | G18: 1 | J18: 4 | K18: 2 | L18: 4 | M18: 4 | N18: 2 | P18: 1 | R18: 3 | S18: 5 | U18: 2 | V18: 4 | W18: 5 | X18: 1 | AA18: 5 | AC18: 1 | AF18: 4 | AH18: 1 | AJ18: 2 | AL18: 2 | AM18: 1 | AN18: 3 | AR18: 4 | AS18: 1 | AT18: 2 | AV18: 3 | AX18: 2 | AY18: 4
A19: The Godfather | B19: 1 | C19: 3 | D19: 4 | E19: 1 | F19: 2 | G19: 3 | H19: 5 | I19: 5 | J19: 3 | K19: 2 | M19: 5 | N19: 2 | O19: 1 | Q19: 3 | S19: 3 | T19: 1 | U19: 5 | W19: 4 | X19: 2 | Y19: 1 | Z19: 4 | AB19: 3 | AC19: 3 | AD19: 5 | AF19: 5 | AG19: 2 | AI19: 3 | AJ19: 2 | AK19: 5 | AL19: 1 | AM19: 1 | AO19: 5 | AP19: 5 | AQ19: 2 | AR19: 3 | AS19: 2 | AU19: 3 | AV19: 3 | AW19: 2 | AX19: 4 | AY19: 3
A20: Harry Potter and the Sorcerer's Stone | B20: 4 | C20: 4 | D20: 5 | E20: 2 | F20: 4 | G20: 5 | I20: 2 | J20: 5 | K20: 5 | L20: 5 | N20: 4 | O20: 3 | Q20: 4 | R20: 5 | T20: 4 | U20: 4 | V20: 4 | X20: 3 | Y20: 3 | Z20: 4 | AA20: 3 | AB20: 2 | AC20: 4 | AE20: 4 | AF20: 3 | AH20: 2 | AI20: 4 | AJ20: 5 | AK20: 5 | AM20: 2 | AN20: 2 | AO20: 4 | AR20: 2 | AS20: 3 | AT20: 3 | AV20: 4 | AW20: 4 | AX20: 4
A21: Home Alone | B21: 5 | C21: 5 | D21: 3 | E21: 2 | F21: 5 | H21: 2 | I21: 3 | K21: 5 | L21: 3 | O21: 4 | P21: 1 | Q21: 4 | S21: 3 | T21: 5 | U21: 2 | W21: 3 | X21: 2 | Z21: 3 | AA21: 2 | AB21: 5 | AD21: 1 | AE21: 2 | AG21: 5 | AH21: 3 | AJ21: 5 | AK21: 5 | AL21: 4 | AM21: 2 | AO21: 3 | AP21: 5 | AQ21: 3 | AS21: 1 | AT21: 4 | AU21: 5 | AW21: 4 | AX21: 2 | AY21: 4

Sheet Correlation25%
A1: Tabel 1
B2: Santa Claus | C2: Gandalf the Grey | D2: Frodo Baggins | E2: Anna | F2: Olaf | G2: Wall-E | H2: Jack Sparrow | I2: Voldemort | J2: Harry Potter | K2: Hagrid | L2: Hermione Granger | M2: Batman | N2: Superman | O2: Minion | P2: Wednesday Adams | Q2: Woody | R2: Captain Kirk | S2: Wolverine | T2: Forrest Gump | U2: Darth Vader | V2: James Bond | W2: Indiana Jones | X2: Barbie | Y2: Cinderella | Z2: Rapunzel | AA2: Pocahontas | AB2: Kermit the Frog | AC2: Miss Piggy | AD2: The Joker | AE2: Katniss Everdeen | AF2: Hannibal Lector | AG2: Chandler Bing | AH2: Rachel Green | AI2: Ross Geller | AJ2: Phoebe Buffay | AK2: Joey Tribiani | AL2: Monica Geller | AM2: Winnie the Pooh | AN2: Dorothy | AO2: Jason Bourne | AP2: Kevin McCallister | AQ2: Regina George | AR2: Shrek | AS2: Professor Snape | AT2: Mr. Bean | AU2: Willy Wonka | AV2: Truman Burbank | AW2: Rudolf the Red-Nosed Reindeer | AX2: Dracula | AY2: Sherlock Holmes
A3: Santa Claus | B3: =CORREL('DATASET 25%'!$B2:$B21,'DATASET 25%'!B2:B21) -> 1 | C3: =CORREL('DATASET 25%'!$B2:$B21,'DATASET 25%'!C2:C21) -> 0.74406979 | D3: =CORREL('DATASET 25%'!$B2:$B21,'DATASET 25%'!D2:D21) -> -0.22334638 | E3: =CORREL('DATASET 25%'!$B2:$B21,'DATASET 25%'!E2:E21) -> 0.53435131 | F3: =CORREL('DATASET 25%'!$B2:$B21,'DATASET 25%'!F2:F21) -> 0.8748708 | G3: =CORREL('DATASET 25%'!$B2:$B21,'DATASET 25%'!G2:G21) -> 0.34684399 | H3: =CORREL('DATASET 25%'!$B2:$B21,'DATASET 25%'!H2:H21) -> -0.19701804 | I3: =CORREL('DATASET 25%'!$B2:$B21,'DATASET 25%'!I2:I21) -> -0.78470603 | ... AY3: =CORREL('DATASET 25%'!$B2:$B21,'DATASET 25%'!AY2:AY21) -> -0.15048232
A4: Gandalf the Grey | B4: =CORREL('DATASET 25%'!$C2:$C21,'DATASET 25%'!B2:B21) -> 0.74406979 | C4: =CORREL('DATASET 25%'!$C2:$C21,'DATASET 25%'!C2:C21) -> 1 | D4: =CORREL('DATASET 25%'!$C2:$C21,'DATASET 25%'!D2:D21) -> 0.27568047 | E4: =CORREL('DATASET 25%'!$C2:$C21,'DATASET 25%'!E2:E21) -> 0.44475421 | F4: =CORREL('DATASET 25%'!$C2:$C21,'DATASET 25%'!F2:F21) -> 0.27931019 | G4: =CORREL('DATASET 25%'!$C2:$C21,'DATASET 25%'!G2:G21) -> -0.045033583 | H4: =CORREL('DATASET 25%'!$C2:$C21,'DATASET 25%'!H2:H21) -> 0.36951073 | I4: =CORREL('DATASET 25%'!$C2:$C21,'DATASET 25%'!I2:I21) -> -0.23259231 | ... AY4: =CORREL('DATASET 25%'!$C2:$C21,'DATASET 25%'!AY2:AY21) -> 0.63245553
A5: Frodo Baggins | B5: =CORREL('DATASET 25%'!$D2:$D21,'DATASET 25%'!B2:B21) -> -0.22334638 | C5: =CORREL('DATASET 25%'!$D2:$D21,'DATASET 25%'!C2:C21) -> 0.27568047 | D5: =CORREL('DATASET 25%'!$D2:$D21,'DATASET 25%'!D2:D21) -> 1 | E5: =CORREL('DATASET 25%'!$D2:$D21,'DATASET 25%'!E2:E21) -> -0.042395585 | F5: =CORREL('DATASET 25%'!$D2:$D21,'DATASET 25%'!F2:F21) -> -0.15447372 | G5: =CORREL('DATASET 25%'!$D2:$D21,'DATASET 25%'!G2:G21) -> 0.24333213 | H5: =CORREL('DATASET 25%'!$D2:$D21,'DATASET 25%'!H2:H21) -> 0.4417261 | I5: =CORREL('DATASET 25%'!$D2:$D21,'DATASET 25%'!I2:I21) -> -0.065128807 | ... AY5: =CORREL('DATASET 25%'!$D2:$D21,'DATASET 25%'!AY2:AY21) -> 0.79020979
A6: Anna | B6: =CORREL('DATASET 25%'!$E2:$E21,'DATASET 25%'!B2:B21) -> 0.53435131 | C6: =CORREL('DATASET 25%'!$E2:$E21,'DATASET 25%'!C2:C21) -> 0.44475421 | D6: =CORREL('DATASET 25%'!$E2:$E21,'DATASET 25%'!D2:D21) -> -0.042395585 | E6: =CORREL('DATASET 25%'!$E2:$E21,'DATASET 25%'!E2:E21) -> 1 | F6: =CORREL('DATASET 25%'!$E2:$E21,'DATASET 25%'!F2:F21) -> 0.2114454 | G6: =CORREL('DATASET 25%'!$E2:$E21,'DATASET 25%'!G2:G21) -> -0.016356609 | H6: =CORREL('DATASET 25%'!$E2:$E21,'DATASET 25%'!H2:H21) -> -0.21197792 | I6: =CORREL('DATASET 25%'!$E2:$E21,'DATASET 25%'!I2:I21) -> -0.64715874 | ... AY6: =CORREL('DATASET 25%'!$E2:$E21,'DATASET 25%'!AY2:AY21) -> -0.34614676
A7: Olaf | B7: =CORREL('DATASET 25%'!$F2:$F21,'DATASET 25%'!B2:B21) -> 0.8748708 | C7: =CORREL('DATASET 25%'!$F2:$F21,'DATASET 25%'!C2:C21) -> 0.27931019 | D7: =CORREL('DATASET 25%'!$F2:$F21,'DATASET 25%'!D2:D21) -> -0.15447372 | E7: =CORREL('DATASET 25%'!$F2:$F21,'DATASET 25%'!E2:E21) -> 0.2114454 | F7: =CORREL('DATASET 25%'!$F2:$F21,'DATASET 25%'!F2:F21) -> 1 | G7: =CORREL('DATASET 25%'!$F2:$F21,'DATASET 25%'!G2:G21) -> 0.46633689 | H7: =CORREL('DATASET 25%'!$F2:$F21,'DATASET 25%'!H2:H21) -> -0.41853903 | I7: =CORREL('DATASET 25%'!$F2:$F21,'DATASET 25%'!I2:I21) -> -0.56895904 | ... AY7: =CORREL('DATASET 25%'!$F2:$F21,'DATASET 25%'!AY2:AY21) -> -0.21582074
A8: Wall-E | B8: =CORREL('DATASET 25%'!$G2:$G21,'DATASET 25%'!B2:B21) -> 0.34684399 | C8: =CORREL('DATASET 25%'!$G2:$G21,'DATASET 25%'!C2:C21) -> -0.045033583 | D8: =CORREL('DATASET 25%'!$G2:$G21,'DATASET 25%'!D2:D21) -> 0.24333213 | E8: =CORREL('DATASET 25%'!$G2:$G21,'DATASET 25%'!E2:E21) -> -0.016356609 | F8: =CORREL('DATASET 25%'!$G2:$G21,'DATASET 25%'!F2:F21) -> 0.46633689 | G8: =CORREL('DATASET 25%'!$G2:$G21,'DATASET 25%'!G2:G21) -> 1 | H8: =CORREL('DATASET 25%'!$G2:$G21,'DATASET 25%'!H2:H21) -> -0.39528471 | I8: =CORREL('DATASET 25%'!$G2:$G21,'DATASET 25%'!I2:I21) -> -0.31785363 | ... AY8: =CORREL('DATASET 25%'!$G2:$G21,'DATASET 25%'!AY2:AY21) -> -0.55988472
A9: Jack Sparrow | B9: =CORREL('DATASET 25%'!$H2:$H21,'DATASET 25%'!B2:B21) -> -0.19701804 | C9: =CORREL('DATASET 25%'!$H2:$H21,'DATASET 25%'!C2:C21) -> 0.36951073 | D9: =CORREL('DATASET 25%'!$H2:$H21,'DATASET 25%'!D2:D21) -> 0.4417261 | E9: =CORREL('DATASET 25%'!$H2:$H21,'DATASET 25%'!E2:E21) -> -0.21197792 | F9: =CORREL('DATASET 25%'!$H2:$H21,'DATASET 25%'!F2:F21) -> -0.41853903 | G9: =CORREL('DATASET 25%'!$H2:$H21,'DATASET 25%'!G2:G21) -> -0.39528471 | H9: =CORREL('DATASET 25%'!$H2:$H21,'DATASET 25%'!H2:H21) -> 1 | I9: =CORREL('DATASET 25%'!$H2:$H21,'DATASET 25%'!I2:I21) -> 0.14327918 | ... AY9: =CORREL('DATASET 25%'!$H2:$H21,'DATASET 25%'!AY2:AY21) -> 0.43082022
A10: Voldemort | B10: =CORREL('DATASET 25%'!$I2:$I21,'DATASET 25%'!B2:B21) -> -0.78470603 | C10: =CORREL('DATASET 25%'!$I2:$I21,'DATASET 25%'!C2:C21) -> -0.23259231 | D10: =CORREL('DATASET 25%'!$I2:$I21,'DATASET 25%'!D2:D21) -> -0.065128807 | E10: =CORREL('DATASET 25%'!$I2:$I21,'DATASET 25%'!E2:E21) -> -0.64715874 | F10: =CORREL('DATASET 25%'!$I2:$I21,'DATASET 25%'!F2:F21) -> -0.56895904 | G10: =CORREL('DATASET 25%'!$I2:$I21,'DATASET 25%'!G2:G21) -> -0.31785363 | H10: =CORREL('DATASET 25%'!$I2:$I21,'DATASET 25%'!H2:H21) -> 0.14327918 | I10: =CORREL('DATASET 25%'!$I2:$I21,'DATASET 25%'!I2:I21) -> 1 | ... AY10: =CORREL('DATASET 25%'!$I2:$I21,'DATASET 25%'!AY2:AY21) -> 0.40499884
A11: Harry Potter | B11: =CORREL('DATASET 25%'!$J2:$J21,'DATASET 25%'!B2:B21) -> -0.075697211 | C11: =CORREL('DATASET 25%'!$J2:$J21,'DATASET 25%'!C2:C21) -> 0.56551442 | D11: =CORREL('DATASET 25%'!$J2:$J21,'DATASET 25%'!D2:D21) -> 0.59702961 | E11: =CORREL('DATASET 25%'!$J2:$J21,'DATASET 25%'!E2:E21) -> -0.2872038 | F11: =CORREL('DATASET 25%'!$J2:$J21,'DATASET 25%'!F2:F21) -> -0.071411495 | G11: =CORREL('DATASET 25%'!$J2:$J21,'DATASET 25%'!G2:G21) -> 0.17808219 | H11: =CORREL('DATASET 25%'!$J2:$J21,'DATASET 25%'!H2:H21) -> 0.31625766 | I11: =CORREL('DATASET 25%'!$J2:$J21,'DATASET 25%'!I2:I21) -> 0.19867985 | ... AY11: =CORREL('DATASET 25%'!$J2:$J21,'DATASET 25%'!AY2:AY21) -> 0.73610964
A12: Hagrid | B12: =CORREL('DATASET 25%'!$K2:$K21,'DATASET 25%'!B2:B21) -> 0.66436384 | C12: =CORREL('DATASET 25%'!$K2:$K21,'DATASET 25%'!C2:C21) -> 0.62305598 | D12: =CORREL('DATASET 25%'!$K2:$K21,'DATASET 25%'!D2:D21) -> 0.052128604 | E12: =CORREL('DATASET 25%'!$K2:$K21,'DATASET 25%'!E2:E21) -> 0.37470636 | F12: =CORREL('DATASET 25%'!$K2:$K21,'DATASET 25%'!F2:F21) -> 0.43629153 | G12: =CORREL('DATASET 25%'!$K2:$K21,'DATASET 25%'!G2:G21) -> 0.58450569 | H12: =CORREL('DATASET 25%'!$K2:$K21,'DATASET 25%'!H2:H21) -> -0.51005892 | I12: =CORREL('DATASET 25%'!$K2:$K21,'DATASET 25%'!I2:I21) -> -0.50795175 | ... AY12: =CORREL('DATASET 25%'!$K2:$K21,'DATASET 25%'!AY2:AY21) -> -0.08304548
A13: Hermione Granger | B13: =CORREL('DATASET 25%'!$L2:$L21,'DATASET 25%'!B2:B21) -> -0.22507035 | C13: =CORREL('DATASET 25%'!$L2:$L21,'DATASET 25%'!C2:C21) -> 0.32084231 | D13: =CORREL('DATASET 25%'!$L2:$L21,'DATASET 25%'!D2:D21) -> 0.54348994 | E13: =CORREL('DATASET 25%'!$L2:$L21,'DATASET 25%'!E2:E21) -> -0.35261557 | F13: =CORREL('DATASET 25%'!$L2:$L21,'DATASET 25%'!F2:F21) -> -0.20847901 | G13: =CORREL('DATASET 25%'!$L2:$L21,'DATASET 25%'!G2:G21) -> 0.056136089 | H13: =CORREL('DATASET 25%'!$L2:$L21,'DATASET 25%'!H2:H21) -> 0.4317297 | I13: =CORREL('DATASET 25%'!$L2:$L21,'DATASET 25%'!I2:I21) -> -0.21270395 | ... AY13: =CORREL('DATASET 25%'!$L2:$L21,'DATASET 25%'!AY2:AY21) -> 0.39125402
A14: Batman | B14: =CORREL('DATASET 25%'!$M2:$M21,'DATASET 25%'!B2:B21) -> -0.6845241 | C14: =CORREL('DATASET 25%'!$M2:$M21,'DATASET 25%'!C2:C21) -> -0.57383973 | D14: =CORREL('DATASET 25%'!$M2:$M21,'DATASET 25%'!D2:D21) -> 0.12055276 | E14: =CORREL('DATASET 25%'!$M2:$M21,'DATASET 25%'!E2:E21) -> -0.93923866 | F14: =CORREL('DATASET 25%'!$M2:$M21,'DATASET 25%'!F2:F21) -> -0.32659863 | G14: =CORREL('DATASET 25%'!$M2:$M21,'DATASET 25%'!G2:G21) -> -0.044669276 | H14: =CORREL('DATASET 25%'!$M2:$M21,'DATASET 25%'!H2:H21) -> 0.2292273 | I14: =CORREL('DATASET 25%'!$M2:$M21,'DATASET 25%'!I2:I21) -> 0.75652126 | ... AY14: =CORREL('DATASET 25%'!$M2:$M21,'DATASET 25%'!AY2:AY21) -> 0.28562508
A15: Superman | B15: =CORREL('DATASET 25%'!$N2:$N21,'DATASET 25%'!B2:B21) -> -0.18573082 | C15: =CORREL('DATASET 25%'!$N2:$N21,'DATASET 25%'!C2:C21) -> -0.22482665 | D15: =CORREL('DATASET 25%'!$N2:$N21,'DATASET 25%'!D2:D21) -> 0.34848736 | E15: =CORREL('DATASET 25%'!$N2:$N21,'DATASET 25%'!E2:E21) -> 0 | F15: =CORREL('DATASET 25%'!$N2:$N21,'DATASET 25%'!F2:F21) -> -0.554274 | G15: =CORREL('DATASET 25%'!$N2:$N21,'DATASET 25%'!G2:G21) -> 0.28062638 | H15: =CORREL('DATASET 25%'!$N2:$N21,'DATASET 25%'!H2:H21) -> -0.26211903 | I15: =CORREL('DATASET 25%'!$N2:$N21,'DATASET 25%'!I2:I21) -> -0.10692147 | ... AY15: =CORREL('DATASET 25%'!$N2:$N21,'DATASET 25%'!AY2:AY21) -> 0.089280538
A16: Minion | B16: =CORREL('DATASET 25%'!$O2:$O21,'DATASET 25%'!B2:B21) -> 0.83542431 | C16: =CORREL('DATASET 25%'!$O2:$O21,'DATASET 25%'!C2:C21) -> 0.45965695 | D16: =CORREL('DATASET 25%'!$O2:$O21,'DATASET 25%'!D2:D21) -> -0.21677749 | E16: =CORREL('DATASET 25%'!$O2:$O21,'DATASET 25%'!E2:E21) -> 0.72599689 | F16: =CORREL('DATASET 25%'!$O2:$O21,'DATASET 25%'!F2:F21) -> 0.8650493 | G16: =CORREL('DATASET 25%'!$O2:$O21,'DATASET 25%'!G2:G21) -> 0.57945683 | H16: =CORREL('DATASET 25%'!$O2:$O21,'DATASET 25%'!H2:H21) -> -0.75877736 | I16: =CORREL('DATASET 25%'!$O2:$O21,'DATASET 25%'!I2:I21) -> -0.58758612 | ... AY16: =CORREL('DATASET 25%'!$O2:$O21,'DATASET 25%'!AY2:AY21) -> -0.39220568
A17: Wednesday Adams | B17: =CORREL('DATASET 25%'!$P2:$P21,'DATASET 25%'!B2:B21) -> -0.70317994 | C17: =CORREL('DATASET 25%'!$P2:$P21,'DATASET 25%'!C2:C21) -> -0.51031036 | D17: =CORREL('DATASET 25%'!$P2:$P21,'DATASET 25%'!D2:D21) -> -0.36430837 | E17: =CORREL('DATASET 25%'!$P2:$P21,'DATASET 25%'!E2:E21) -> -0.75664445 | F17: =CORREL('DATASET 25%'!$P2:$P21,'DATASET 25%'!F2:F21) -> -0.69467703 | G17: =CORREL('DATASET 25%'!$P2:$P21,'DATASET 25%'!G2:G21) -> -0.46633689 | H17: =CORREL('DATASET 25%'!$P2:$P21,'DATASET 25%'!H2:H21) -> 0.3592106 | I17: =CORREL('DATASET 25%'!$P2:$P21,'DATASET 25%'!I2:I21) -> 0.86102807 | ... AY17: =CORREL('DATASET 25%'!$P2:$P21,'DATASET 25%'!AY2:AY21) -> 0.1490712
A18: Woody | B18: =CORREL('DATASET 25%'!$Q2:$Q21,'DATASET 25%'!B2:B21) -> 0.047036043 | C18: =CORREL('DATASET 25%'!$Q2:$Q21,'DATASET 25%'!C2:C21) -> 0.42499682 | D18: =CORREL('DATASET 25%'!$Q2:$Q21,'DATASET 25%'!D2:D21) -> 0.53763957 | E18: =CORREL('DATASET 25%'!$Q2:$Q21,'DATASET 25%'!E2:E21) -> 0 | F18: =CORREL('DATASET 25%'!$Q2:$Q21,'DATASET 25%'!F2:F21) -> -0.094609454 | G18: =CORREL('DATASET 25%'!$Q2:$Q21,'DATASET 25%'!G2:G21) -> 0.35806724 | H18: =CORREL('DATASET 25%'!$Q2:$Q21,'DATASET 25%'!H2:H21) -> 0.3250418 | I18: =CORREL('DATASET 25%'!$Q2:$Q21,'DATASET 25%'!I2:I21) -> -0.12108987 | ... AY18: =CORREL('DATASET 25%'!$Q2:$Q21,'DATASET 25%'!AY2:AY21) -> -0.1
A19: Captain Kirk | B19: =CORREL('DATASET 25%'!$R2:$R21,'DATASET 25%'!B2:B21) -> -0.25057829 | C19: =CORREL('DATASET 25%'!$R2:$R21,'DATASET 25%'!C2:C21) -> -0.036860489 | D19: =CORREL('DATASET 25%'!$R2:$R21,'DATASET 25%'!D2:D21) -> 0.68401333 | E19: =CORREL('DATASET 25%'!$R2:$R21,'DATASET 25%'!E2:E21) -> -0.66575405 | F19: =CORREL('DATASET 25%'!$R2:$R21,'DATASET 25%'!F2:F21) -> -0.060559517 | G19: =CORREL('DATASET 25%'!$R2:$R21,'DATASET 25%'!G2:G21) -> 0.5089788 | H19: =CORREL('DATASET 25%'!$R2:$R21,'DATASET 25%'!H2:H21) -> 0.12888482 | I19: =CORREL('DATASET 25%'!$R2:$R21,'DATASET 25%'!I2:I21) -> 0.2981424 | ... AY19: =CORREL('DATASET 25%'!$R2:$R21,'DATASET 25%'!AY2:AY21) -> 0.57896373
A20: Wolverine | B20: =CORREL('DATASET 25%'!$S2:$S21,'DATASET 25%'!B2:B21) -> -0.61819859 | C20: =CORREL('DATASET 25%'!$S2:$S21,'DATASET 25%'!C2:C21) -> -0.05414351 | D20: =CORREL('DATASET 25%'!$S2:$S21,'DATASET 25%'!D2:D21) -> 0.61786757 | E20: =CORREL('DATASET 25%'!$S2:$S21,'DATASET 25%'!E2:E21) -> -0.65423313 | F20: =CORREL('DATASET 25%'!$S2:$S21,'DATASET 25%'!F2:F21) -> -0.49718308 | G20: =CORREL('DATASET 25%'!$S2:$S21,'DATASET 25%'!G2:G21) -> -0.36097088 | H20: =CORREL('DATASET 25%'!$S2:$S21,'DATASET 25%'!H2:H21) -> 0.4755699 | I20: =CORREL('DATASET 25%'!$S2:$S21,'DATASET 25%'!I2:I21) -> 0.76655518 | ... AY20: =CORREL('DATASET 25%'!$S2:$S21,'DATASET 25%'!AY2:AY21) -> 0.67856422
A21: Forrest Gump | B21: =CORREL('DATASET 25%'!$T2:$T21,'DATASET 25%'!B2:B21) -> 0.92069431 | C21: =CORREL('DATASET 25%'!$T2:$T21,'DATASET 25%'!C2:C21) -> 0.42729611 | D21: =CORREL('DATASET 25%'!$T2:$T21,'DATASET 25%'!D2:D21) -> 0 | E21: =CORREL('DATASET 25%'!$T2:$T21,'DATASET 25%'!E2:E21) -> 0.72083359 | F21: =CORREL('DATASET 25%'!$T2:$T21,'DATASET 25%'!F2:F21) -> 0.80554541 | G21: =CORREL('DATASET 25%'!$T2:$T21,'DATASET 25%'!G2:G21) -> 0.28918811 | H21: =CORREL('DATASET 25%'!$T2:$T21,'DATASET 25%'!H2:H21) -> -0.40560407 | I21: =CORREL('DATASET 25%'!$T2:$T21,'DATASET 25%'!I2:I21) -> -0.64821639 | ... AY21: =CORREL('DATASET 25%'!$T2:$T21,'DATASET 25%'!AY2:AY21) -> -0.25391669
A22: Darth Vader | B22: =CORREL('DATASET 25%'!$U2:$U21,'DATASET 25%'!B2:B21) -> -0.36626598 | C22: =CORREL('DATASET 25%'!$U2:$U21,'DATASET 25%'!C2:C21) -> -0.47524472 | D22: =CORREL('DATASET 25%'!$U2:$U21,'DATASET 25%'!D2:D21) -> 0.10127394 | E22: =CORREL('DATASET 25%'!$U2:$U21,'DATASET 25%'!E2:E21) -> -0.33802043 | F22: =CORREL('DATASET 25%'!$U2:$U21,'DATASET 25%'!F2:F21) -> -0.4173047 | G22: =CORREL('DATASET 25%'!$U2:$U21,'DATASET 25%'!G2:G21) -> -0.038128601 | H22: =CORREL('DATASET 25%'!$U2:$U21,'DATASET 25%'!H2:H21) -> 0.11271158 | I22: =CORREL('DATASET 25%'!$U2:$U21,'DATASET 25%'!I2:I21) -> 0.49130435 | ... AY22: =CORREL('DATASET 25%'!$U2:$U21,'DATASET 25%'!AY2:AY21) -> 0.23150133
A23: James Bond | B23: =CORREL('DATASET 25%'!$V2:$V21,'DATASET 25%'!B2:B21) -> -0.28252897 | C23: =CORREL('DATASET 25%'!$V2:$V21,'DATASET 25%'!C2:C21) -> 0.38924947 | D23: =CORREL('DATASET 25%'!$V2:$V21,'DATASET 25%'!D2:D21) -> 0.80555556 | E23: =CORREL('DATASET 25%'!$V2:$V21,'DATASET 25%'!E2:E21) -> -0.4532471 | F23: =CORREL('DATASET 25%'!$V2:$V21,'DATASET 25%'!F2:F21) -> -0.54260952 | G23: =CORREL('DATASET 25%'!$V2:$V21,'DATASET 25%'!G2:G21) -> -0.34200306 | H23: =CORREL('DATASET 25%'!$V2:$V21,'DATASET 25%'!H2:H21) -> 0.87995526 | I23: =CORREL('DATASET 25%'!$V2:$V21,'DATASET 25%'!I2:I21) -> 0.312378 | ... AY23: =CORREL('DATASET 25%'!$V2:$V21,'DATASET 25%'!AY2:AY21) -> 0.70417879
A24: Indiana Jones | B24: =CORREL('DATASET 25%'!$W2:$W21,'DATASET 25%'!B2:B21) -> -0.46915887 | C24: =CORREL('DATASET 25%'!$W2:$W21,'DATASET 25%'!C2:C21) -> 0.25604806 | D24: =CORREL('DATASET 25%'!$W2:$W21,'DATASET 25%'!D2:D21) -> 0.52486686 | E24: =CORREL('DATASET 25%'!$W2:$W21,'DATASET 25%'!E2:E21) -> -0.64226163 | F24: =CORREL('DATASET 25%'!$W2:$W21,'DATASET 25%'!F2:F21) -> -0.32970016 | G24: =CORREL('DATASET 25%'!$W2:$W21,'DATASET 25%'!G2:G21) -> -0.04710775 | H24: =CORREL('DATASET 25%'!$W2:$W21,'DATASET 25%'!H2:H21) -> 0.45342519 | I24: =CORREL('DATASET 25%'!$W2:$W21,'DATASET 25%'!I2:I21) -> 0.24144312 | ... AY24: =CORREL('DATASET 25%'!$W2:$W21,'DATASET 25%'!AY2:AY21) -> 0.68250015
A25: Barbie | B25: =CORREL('DATASET 25%'!$X2:$X21,'DATASET 25%'!B2:B21) -> 0.65198971 | C25: =CORREL('DATASET 25%'!$X2:$X21,'DATASET 25%'!C2:C21) -> 0.49208226 | D25: =CORREL('DATASET 25%'!$X2:$X21,'DATASET 25%'!D2:D21) -> -0.19706586 | E25: =CORREL('DATASET 25%'!$X2:$X21,'DATASET 25%'!E2:E21) -> 0.85092474 | F25: =CORREL('DATASET 25%'!$X2:$X21,'DATASET 25%'!F2:F21) -> 0.48078072 | G25: =CORREL('DATASET 25%'!$X2:$X21,'DATASET 25%'!G2:G21) -> 0.33839674 | H25: =CORREL('DATASET 25%'!$X2:$X21,'DATASET 25%'!H2:H21) -> -0.1877293 | I25: =CORREL('DATASET 25%'!$X2:$X21,'DATASET 25%'!I2:I21) -> -0.62546279 | ... AY25: =CORREL('DATASET 25%'!$X2:$X21,'DATASET 25%'!AY2:AY21) -> -0.44950221
A26: Cinderella | B26: =CORREL('DATASET 25%'!$Y2:$Y21,'DATASET 25%'!B2:B21) -> 0.87454589 | C26: =CORREL('DATASET 25%'!$Y2:$Y21,'DATASET 25%'!C2:C21) -> 0.36806572 | D26: =CORREL('DATASET 25%'!$Y2:$Y21,'DATASET 25%'!D2:D21) -> -0.15041421 | E26: =CORREL('DATASET 25%'!$Y2:$Y21,'DATASET 25%'!E2:E21) -> 0.76996785 | F26: =CORREL('DATASET 25%'!$Y2:$Y21,'DATASET 25%'!F2:F21) -> 0.69398668 | G26: =CORREL('DATASET 25%'!$Y2:$Y21,'DATASET 25%'!G2:G21) -> 0.21248647 | H26: =CORREL('DATASET 25%'!$Y2:$Y21,'DATASET 25%'!H2:H21) -> -0.35602621 | I26: =CORREL('DATASET 25%'!$Y2:$Y21,'DATASET 25%'!I2:I21) -> -0.77786332 | ... AY26: =CORREL('DATASET 25%'!$Y2:$Y21,'DATASET 25%'!AY2:AY21) -> -0.60647843
A27: Rapunzel | B27: =CORREL('DATASET 25%'!$Z2:$Z21,'DATASET 25%'!B2:B21) -> 0.55669003 | C27: =CORREL('DATASET 25%'!$Z2:$Z21,'DATASET 25%'!C2:C21) -> 0.48073411 | D27: =CORREL('DATASET 25%'!$Z2:$Z21,'DATASET 25%'!D2:D21) -> 0.41414612 | E27: =CORREL('DATASET 25%'!$Z2:$Z21,'DATASET 25%'!E2:E21) -> 0.42589714 | F27: =CORREL('DATASET 25%'!$Z2:$Z21,'DATASET 25%'!F2:F21) -> 0.35154007 | G27: =CORREL('DATASET 25%'!$Z2:$Z21,'DATASET 25%'!G2:G21) -> 0.14803913 | H27: =CORREL('DATASET 25%'!$Z2:$Z21,'DATASET 25%'!H2:H21) -> 0.26550619 | I27: =CORREL('DATASET 25%'!$Z2:$Z21,'DATASET 25%'!I2:I21) -> -0.56921859 | ... AY27: =CORREL('DATASET 25%'!$Z2:$Z21,'DATASET 25%'!AY2:AY21) -> 0.11347803
A28: Pocahontas | B28: =CORREL('DATASET 25%'!$AA2:$AA21,'DATASET 25%'!B2:B21) -> -0.26297184 | C28: =CORREL('DATASET 25%'!$AA2:$AA21,'DATASET 25%'!C2:C21) -> -0.25925926 | D28: =CORREL('DATASET 25%'!$AA2:$AA21,'DATASET 25%'!D2:D21) -> 0.52972573 | E28: =CORREL('DATASET 25%'!$AA2:$AA21,'DATASET 25%'!E2:E21) -> 0.33618469 | F28: =CORREL('DATASET 25%'!$AA2:$AA21,'DATASET 25%'!F2:F21) -> -0.25509418 | G28: =CORREL('DATASET 25%'!$AA2:$AA21,'DATASET 25%'!G2:G21) -> -0.082199494 | H28: =CORREL('DATASET 25%'!$AA2:$AA21,'DATASET 25%'!H2:H21) -> 0.17566515 | I28: =CORREL('DATASET 25%'!$AA2:$AA21,'DATASET 25%'!I2:I21) -> -0.10191356 | ... AY28: =CORREL('DATASET 25%'!$AA2:$AA21,'DATASET 25%'!AY2:AY21) -> 0.24056261
A29: Kermit the Frog | B29: =CORREL('DATASET 25%'!$AB2:$AB21,'DATASET 25%'!B2:B21) -> 0.72536057 | C29: =CORREL('DATASET 25%'!$AB2:$AB21,'DATASET 25%'!C2:C21) -> 0.22581247 | D29: =CORREL('DATASET 25%'!$AB2:$AB21,'DATASET 25%'!D2:D21) -> -0.29318996 | E29: =CORREL('DATASET 25%'!$AB2:$AB21,'DATASET 25%'!E2:E21) -> 0.57123527 | F29: =CORREL('DATASET 25%'!$AB2:$AB21,'DATASET 25%'!F2:F21) -> 0.78604506 | G29: =CORREL('DATASET 25%'!$AB2:$AB21,'DATASET 25%'!G2:G21) -> 0.29335265 | H29: =CORREL('DATASET 25%'!$AB2:$AB21,'DATASET 25%'!H2:H21) -> -0.5815267 | I29: =CORREL('DATASET 25%'!$AB2:$AB21,'DATASET 25%'!I2:I21) -> -0.38367213 | ... AY29: =CORREL('DATASET 25%'!$AB2:$AB21,'DATASET 25%'!AY2:AY21) -> -0.18447879
A30: Miss Piggy | B30: =CORREL('DATASET 25%'!$AC2:$AC21,'DATASET 25%'!B2:B21) -> 0.25361875 | C30: =CORREL('DATASET 25%'!$AC2:$AC21,'DATASET 25%'!C2:C21) -> -0.32510161 | D30: =CORREL('DATASET 25%'!$AC2:$AC21,'DATASET 25%'!D2:D21) -> -0.38145729 | E30: =CORREL('DATASET 25%'!$AC2:$AC21,'DATASET 25%'!E2:E21) -> -0.011135885 | F30: =CORREL('DATASET 25%'!$AC2:$AC21,'DATASET 25%'!F2:F21) -> 0.30658331 | G30: =CORREL('DATASET 25%'!$AC2:$AC21,'DATASET 25%'!G2:G21) -> 0.4960688 | H30: =CORREL('DATASET 25%'!$AC2:$AC21,'DATASET 25%'!H2:H21) -> -0.22415643 | I30: =CORREL('DATASET 25%'!$AC2:$AC21,'DATASET 25%'!I2:I21) -> -0.38311227 | ... AY30: =CORREL('DATASET 25%'!$AC2:$AC21,'DATASET 25%'!AY2:AY21) -> -0.62333479
A31: The Joker | B31: =CORREL('DATASET 25%'!$AD2:$AD21,'DATASET 25%'!B2:B21) -> -0.31252706 | C31: =CORREL('DATASET 25%'!$AD2:$AD21,'DATASET 25%'!C2:C21) -> 0.034539847 | D31: =CORREL('DATASET 25%'!$AD2:$AD21,'DATASET 25%'!D2:D21) -> 0 | E31: =CORREL('DATASET 25%'!$AD2:$AD21,'DATASET 25%'!E2:E21) -> -0.44582257 | F31: =CORREL('DATASET 25%'!$AD2:$AD21,'DATASET 25%'!F2:F21) -> -0.1902606 | G31: =CORREL('DATASET 25%'!$AD2:$AD21,'DATASET 25%'!G2:G21) -> -0.25283778 | H31: =CORREL('DATASET 25%'!$AD2:$AD21,'DATASET 25%'!H2:H21) -> 0.31684721 | I31: =CORREL('DATASET 25%'!$AD2:$AD21,'DATASET 25%'!I2:I21) -> 0.76641919 | ... AY31: =CORREL('DATASET 25%'!$AD2:$AD21,'DATASET 25%'!AY2:AY21) -> 0.44160276
A32: Katniss Everdeen | B32: =CORREL('DATASET 25%'!$AE2:$AE21,'DATASET 25%'!B2:B21) -> -0.65486726 | C32: =CORREL('DATASET 25%'!$AE2:$AE21,'DATASET 25%'!C2:C21) -> -0.49858823 | D32: =CORREL('DATASET 25%'!$AE2:$AE21,'DATASET 25%'!D2:D21) -> 0.54088015 | E32: =CORREL('DATASET 25%'!$AE2:$AE21,'DATASET 25%'!E2:E21) -> -0.58059806 | F32: =CORREL('DATASET 25%'!$AE2:$AE21,'DATASET 25%'!F2:F21) -> -0.34347857 | G32: =CORREL('DATASET 25%'!$AE2:$AE21,'DATASET 25%'!G2:G21) -> 0.54072011 | H32: =CORREL('DATASET 25%'!$AE2:$AE21,'DATASET 25%'!H2:H21) -> 0.17159763 | I32: =CORREL('DATASET 25%'!$AE2:$AE21,'DATASET 25%'!I2:I21) -> 0.29904999 | ... AY32: =CORREL('DATASET 25%'!$AE2:$AE21,'DATASET 25%'!AY2:AY21) -> 0.18376917
A33: Hannibal Lector | B33: =CORREL('DATASET 25%'!$AF2:$AF21,'DATASET 25%'!B2:B21) -> -0.60723271 | C33: =CORREL('DATASET 25%'!$AF2:$AF21,'DATASET 25%'!C2:C21) -> -0.031915183 | D33: =CORREL('DATASET 25%'!$AF2:$AF21,'DATASET 25%'!D2:D21) -> -0.041502868 | E33: =CORREL('DATASET 25%'!$AF2:$AF21,'DATASET 25%'!E2:E21) -> -0.3673873 | F33: =CORREL('DATASET 25%'!$AF2:$AF21,'DATASET 25%'!F2:F21) -> -0.59945803 | G33: =CORREL('DATASET 25%'!$AF2:$AF21,'DATASET 25%'!G2:G21) -> -0.5479246 | H33: =CORREL('DATASET 25%'!$AF2:$AF21,'DATASET 25%'!H2:H21) -> 0.24019223 | I33: =CORREL('DATASET 25%'!$AF2:$AF21,'DATASET 25%'!I2:I21) -> 0.68449833 | ... AY33: =CORREL('DATASET 25%'!$AF2:$AF21,'DATASET 25%'!AY2:AY21) -> 0.46401521
A34: Chandler Bing | B34: =CORREL('DATASET 25%'!$AG2:$AG21,'DATASET 25%'!B2:B21) -> 0.60702355 | C34: =CORREL('DATASET 25%'!$AG2:$AG21,'DATASET 25%'!C2:C21) -> 0.47338107 | D34: =CORREL('DATASET 25%'!$AG2:$AG21,'DATASET 25%'!D2:D21) -> 0.020946922 | E34: =CORREL('DATASET 25%'!$AG2:$AG21,'DATASET 25%'!E2:E21) -> 0.52704628 | F34: =CORREL('DATASET 25%'!$AG2:$AG21,'DATASET 25%'!F2:F21) -> 0.5371352 | G34: =CORREL('DATASET 25%'!$AG2:$AG21,'DATASET 25%'!G2:G21) -> 0.60444733 | H34: =CORREL('DATASET 25%'!$AG2:$AG21,'DATASET 25%'!H2:H21) -> -0.65391269 | I34: =CORREL('DATASET 25%'!$AG2:$AG21,'DATASET 25%'!I2:I21) -> -0.1999003 | ... AY34: =CORREL('DATASET 25%'!$AG2:$AG21,'DATASET 25%'!AY2:AY21) -> -0.3687919
A35: Rachel Green | B35: =CORREL('DATASET 25%'!$AH2:$AH21,'DATASET 25%'!B2:B21) -> 0.34196364 | C35: =CORREL('DATASET 25%'!$AH2:$AH21,'DATASET 25%'!C2:C21) -> -0.3649982 | D35: =CORREL('DATASET 25%'!$AH2:$AH21,'DATASET 25%'!D2:D21) -> -0.52345355 | E35: =CORREL('DATASET 25%'!$AH2:$AH21,'DATASET 25%'!E2:E21) -> 0.10699012 | F35: =CORREL('DATASET 25%'!$AH2:$AH21,'DATASET 25%'!F2:F21) -> 0.56865368 | G35: =CORREL('DATASET 25%'!$AH2:$AH21,'DATASET 25%'!G2:G21) -> 0.63535008 | H35: =CORREL('DATASET 25%'!$AH2:$AH21,'DATASET 25%'!H2:H21) -> -0.5561085 | I35: =CORREL('DATASET 25%'!$AH2:$AH21,'DATASET 25%'!I2:I21) -> -0.39799497 | ... AY35: =CORREL('DATASET 25%'!$AH2:$AH21,'DATASET 25%'!AY2:AY21) -> -0.79875469
A36: Ross Geller | B36: =CORREL('DATASET 25%'!$AI2:$AI21,'DATASET 25%'!B2:B21) -> -0.21755818 | C36: =CORREL('DATASET 25%'!$AI2:$AI21,'DATASET 25%'!C2:C21) -> -0.43631801 | D36: =CORREL('DATASET 25%'!$AI2:$AI21,'DATASET 25%'!D2:D21) -> 0.16374773 | E36: =CORREL('DATASET 25%'!$AI2:$AI21,'DATASET 25%'!E2:E21) -> -0.29615677 | F36: =CORREL('DATASET 25%'!$AI2:$AI21,'DATASET 25%'!F2:F21) -> -0.10039117 | G36: =CORREL('DATASET 25%'!$AI2:$AI21,'DATASET 25%'!G2:G21) -> 0.40915999 | H36: =CORREL('DATASET 25%'!$AI2:$AI21,'DATASET 25%'!H2:H21) -> -0.13102121 | I36: =CORREL('DATASET 25%'!$AI2:$AI21,'DATASET 25%'!I2:I21) -> -0.31550422 | ... AY36: =CORREL('DATASET 25%'!$AI2:$AI21,'DATASET 25%'!AY2:AY21) -> -0.23078317
A37: Phoebe Buffay | B37: =CORREL('DATASET 25%'!$AJ2:$AJ21,'DATASET 25%'!B2:B21) -> 0.66705617 | C37: =CORREL('DATASET 25%'!$AJ2:$AJ21,'DATASET 25%'!C2:C21) -> 0.14619752 | D37: =CORREL('DATASET 25%'!$AJ2:$AJ21,'DATASET 25%'!D2:D21) -> -0.036080477 | E37: =CORREL('DATASET 25%'!$AJ2:$AJ21,'DATASET 25%'!E2:E21) -> 0.13002289 | F37: =CORREL('DATASET 25%'!$AJ2:$AJ21,'DATASET 25%'!F2:F21) -> 0.64260493 | G37: =CORREL('DATASET 25%'!$AJ2:$AJ21,'DATASET 25%'!G2:G21) -> 0.60317312 | H37: =CORREL('DATASET 25%'!$AJ2:$AJ21,'DATASET 25%'!H2:H21) -> -0.57262006 | I37: =CORREL('DATASET 25%'!$AJ2:$AJ21,'DATASET 25%'!I2:I21) -> -0.011207692 | ... AY37: =CORREL('DATASET 25%'!$AJ2:$AJ21,'DATASET 25%'!AY2:AY21) -> -0.077615053
A38: Joey Tribiani | B38: =CORREL('DATASET 25%'!$AK2:$AK21,'DATASET 25%'!B2:B21) -> 0.21177208 | C38: =CORREL('DATASET 25%'!$AK2:$AK21,'DATASET 25%'!C2:C21) -> -0.0087567823 | D38: =CORREL('DATASET 25%'!$AK2:$AK21,'DATASET 25%'!D2:D21) -> 0.56615644 | E38: =CORREL('DATASET 25%'!$AK2:$AK21,'DATASET 25%'!E2:E21) -> -0.17505997 | F38: =CORREL('DATASET 25%'!$AK2:$AK21,'DATASET 25%'!F2:F21) -> 0.30981353 | G38: =CORREL('DATASET 25%'!$AK2:$AK21,'DATASET 25%'!G2:G21) -> 0.71858087 | H38: =CORREL('DATASET 25%'!$AK2:$AK21,'DATASET 25%'!H2:H21) -> -0.020463638 | I38: =CORREL('DATASET 25%'!$AK2:$AK21,'DATASET 25%'!I2:I21) -> 0.044457592 | ... AY38: =CORREL('DATASET 25%'!$AK2:$AK21,'DATASET 25%'!AY2:AY21) -> 0.25680396
A39: Monica Geller | B39: =CORREL('DATASET 25%'!$AL2:$AL21,'DATASET 25%'!B2:B21) -> 0.5724923 | C39: =CORREL('DATASET 25%'!$AL2:$AL21,'DATASET 25%'!C2:C21) -> 0.21611068 | D39: =CORREL('DATASET 25%'!$AL2:$AL21,'DATASET 25%'!D2:D21) -> 0.048261709 | E39: =CORREL('DATASET 25%'!$AL2:$AL21,'DATASET 25%'!E2:E21) -> 0.11489313 | F39: =CORREL('DATASET 25%'!$AL2:$AL21,'DATASET 25%'!F2:F21) -> 0.17999125 | G39: =CORREL('DATASET 25%'!$AL2:$AL21,'DATASET 25%'!G2:G21) -> -0.43112399 | H39: =CORREL('DATASET 25%'!$AL2:$AL21,'DATASET 25%'!H2:H21) -> 0.10033501 | I39: =CORREL('DATASET 25%'!$AL2:$AL21,'DATASET 25%'!I2:I21) -> -0.32219167 | ... AY39: =CORREL('DATASET 25%'!$AL2:$AL21,'DATASET 25%'!AY2:AY21) -> 0.38748758
A40: Winnie the Pooh | B40: =CORREL('DATASET 25%'!$AM2:$AM21,'DATASET 25%'!B2:B21) -> 0.54594073 | C40: =CORREL('DATASET 25%'!$AM2:$AM21,'DATASET 25%'!C2:C21) -> 0.23775808 | D40: =CORREL('DATASET 25%'!$AM2:$AM21,'DATASET 25%'!D2:D21) -> -0.19130533 | E40: =CORREL('DATASET 25%'!$AM2:$AM21,'DATASET 25%'!E2:E21) -> 0.6054235 | F40: =CORREL('DATASET 25%'!$AM2:$AM21,'DATASET 25%'!F2:F21) -> 0.19523813 | G40: =CORREL('DATASET 25%'!$AM2:$AM21,'DATASET 25%'!G2:G21) -> 0.14607765 | H40: =CORREL('DATASET 25%'!$AM2:$AM21,'DATASET 25%'!H2:H21) -> -0.10576239 | I40: =CORREL('DATASET 25%'!$AM2:$AM21,'DATASET 25%'!I2:I21) -> -0.40760781 | ... AY40: =CORREL('DATASET 25%'!$AM2:$AM21,'DATASET 25%'!AY2:AY21) -> -0.33120207
...

Sheet Wolverine - 25%
A1: Tabel 1
B2: Correlation | C2: Rating | D2: Average Rating | E2: Normalized Rating | F2: Correlation * NR
A3: James Bond | B3: 0.842 | C3: 3 | D3: =AVERAGE('DATASET 25%'!V2:V21) -> 3.2307692 | E3: =C3-D3 -> -0.23076923 | F3: =B3*E3 -> -0.19430769
A4: Kevin McCallister | B4: 0.803 | C4: 1 | D4: =AVERAGE('DATASET 25%'!AP2:AP21) -> 3.3125 | E4: =C4-D4 -> -2.3125 | F4: =B4*E4 -> -1.8569375
A5: Voldemort | B5: 0.767 | C5: 2 | D5: =AVERAGE('DATASET 25%'!I2:I21) -> 3 | E5: =C5-D5 -> -1 | F5: =B5*E5 -> -0.767
A6: Captain Kirk | B6: 0.737 | C6: 3 | D6: =AVERAGE('DATASET 25%'!R2:R21) -> 3.2666667 | E6: =C6-D6 -> -0.26666667 | F6: =B6*E6 -> -0.19653333
A7: Katniss Everdeen | B7: 0.735 | C7: 2 | D7: =AVERAGE('DATASET 25%'!AE2:AE21) -> 2.7142857 | E7: =C7-D7 -> -0.71428571 | F7: =B7*E7 -> -0.525
A8: Sherlock Holmes | B8: 0.679 | C8: 2 | D8: =AVERAGE('DATASET 25%'!AY2:AY21) -> 2.5333333 | E8: =C8-D8 -> -0.53333333 | F8: =B8*E8 -> -0.36213333
A9: Batman | B9: 0.66 | C9: 2 | D9: =AVERAGE('DATASET 25%'!M2:M21) -> 2.4666667 | E9: =C9-D9 -> -0.46666667 | F9: =B9*E9 -> -0.308
A10: Frodo Baggins | B10: 0.618 | C10: 2 | D10: =AVERAGE('DATASET 25%'!D2:D21) -> 3.1333333 | E10: =C10-D10 -> -1.1333333 | F10: =B10*E10 -> -0.7004
A11: Harry Potter | B11: 0.573 | C11: 3 | D11: =AVERAGE('DATASET 25%'!J2:J21) -> 3 | E11: =C11-D11 -> 0 | F11: =B11*E11 -> 0
A12: Hannibal Lector | B12: 0.567 | C12: 0 | D12: =AVERAGE('DATASET 25%'!AF2:AF21) -> 3.5 | E12: 0 | F12: =B12*E12 -> 0
A13: Indiana Jones | B13: 0.565 | C13: 4 | D13: =AVERAGE('DATASET 25%'!W2:W21) -> 3.4 | E13: =C13-D13 -> 0.6 | F13: =B13*E13 -> 0.339
A14: Pocahontas | B14: 0.551 | C14: 4 | D14: =AVERAGE('DATASET 25%'!AA2:AA21) -> 3.5333333 | E14: =C14-D14 -> 0.46666667 | F14: =B14*E14 -> 0.25713333
A15: Wednesday Adams | B15: 0.511 | C15: 1 | D15: =AVERAGE('DATASET 25%'!P2:P21) -> 1.6153846 | E15: =C15-D15 -> -0.61538462 | F15: =B15*E15 -> -0.31446154
E16: Predicted Normalized Rating | F16: =SUM(F3:F8)/SUM(B3:B8) -> -0.85511985
D17: =AVERAGE('DATASET 25%'!S2:S21) -> 2.5333333 | E17: Predicted Rating | F17: =F16+AVERAGE('DATASET 25%'!S2:S21) -> 1.6782135
